<?xml version='1.0'?>

<robot name="my_robot" xmlns:xacro="http://www.ros.org/wiki/xacro">
<xacro:include filename="$(find my_robot)/urdf/my_robot.gazebo" />

 
  <xacro:property name="PI" value="3.1415926535897931" />

  <xacro:property name="wheel_radius" value="0.050" />
  <xacro:property name="wheel_width" value="0.0505" />

  <material name="yellow"><color rgba="0.8 0.8 0.0 1.0" /></material>
  <material name="black"><color rgba="0.15 0.15 0.15 1.0" /></material>
  <material name="dark_grey"><color rgba="0.2 0.2 0.2 1.0" /></material>
  <material name="light_grey"><color rgba="0.4 0.4 0.4 1.0" /></material>

<!--robot_footprint-->

  <link name="robot_footprint"></link>

  <joint name="robot_footprint_joint" type="fixed">
    <origin xyz="0 0 0.05" rpy="0 0 0" />
    <parent link="robot_footprint"/>
    <child link="chassis" />
  </joint>

<!--chassis-->
  <link name="chassis">
    <visual>
      <origin xyz="0 0 0" rpy="0 0 0" />
      <geometry>
        <mesh filename="package://my_robot/meshes/chassis.STL" scale="0.001 0.001 0.001"/>
      </geometry>
      <material name="yellow" />
    </visual>
    <collision>
      <origin xyz="0 0 0"/>
      <geometry>
        <mesh filename="package://my_robot/meshes/chassis_collision.STL" scale="0.001 0.001 0.001"/>
      </geometry>
    </collision>
    <inertial>
      <!-- Inertia from CAD model, filled box assumption -->
      <origin xyz="-0.01103 0 0.002" rpy="0 0 0"/>
      <mass value="2.844"/>
      <inertia
        ixx="0.018819942" ixy="0" ixz="-0.000101519"
        iyy="0.057333716" iyz="0"
        izz="0.074201740"/>
    </inertial>
  </link>


<!--right_wheel_shaft-->
  <link name="right_wheel_shaft">
    <visual>
      <origin xyz="0 0 0" rpy="0 0 0" />
      <geometry>
        <mesh filename="package://my_robot/meshes/wheel_shaft.STL" scale="0.001 0.001 0.001"/>
      </geometry>
      <material name="black" />
    </visual>
    <collision>
      <origin xyz="0 0 0"/>
      <geometry>
        <mesh filename="package://my_robot/meshes/wheel_shaft.STL" scale="0.001 0.001 0.001"/>
      </geometry>
    </collision>
    <inertial>
      <origin xyz="0 0 0" rpy="0 0 0"/>
      <mass value="0.055"/>
      <inertia
        ixx="0.000021370" ixy="0" ixz="0"
        iyy="0.000009966" iyz="0"
        izz="0.000021370"/>
    </inertial>
  </link>

<!--right_wheel_shaft_joint-->
  <joint name="right_wheel_shaft_joint" type="fixed">
    <origin xyz="0.005 0.108 0" rpy="0 0 0" />
    <parent link="chassis"/>
    <child link="right_wheel_shaft" />
  </joint>


<!--back_right_wheel_shaft-->
  <link name="back_right_wheel_shaft">
    <visual>
      <origin xyz="0 0 0" rpy="0 0 0" />
      <geometry>
        <mesh filename="package://my_robot/meshes/wheel_shaft.STL" scale="0.001 0.001 0.001"/>
      </geometry>
      <material name="black" />
    </visual>
    <collision>
      <origin xyz="0 0 0"/>
      <geometry>
        <mesh filename="package://my_robot/meshes/wheel_shaft.STL" scale="0.001 0.001 0.001"/>
      </geometry>
    </collision>
    <inertial>
      <origin xyz="0 0.01221 0" rpy="0 0 0"/>
      <mass value="0.055"/>
      <inertia
        ixx="0.000021370" ixy="0" ixz="0"
        iyy="0.000009966" iyz="0"
        izz="0.000021370"/>
    </inertial>
  </link>

<!--back_right_wheel_shaft_join-->
  <joint name="back_right_wheel_shaft_joint" type="fixed">
    <origin xyz="-0.150 0.108 0.0" rpy="0 0 0" />
    <parent link="chassis"/>
    <child link="back_right_wheel_shaft" />
  </joint>

<!--left_wheel_shaft-->
  <link name="left_wheel_shaft">
    <visual>
      <origin xyz="0 0 0" rpy="0 0 0" />
      <geometry>
        <mesh filename="package://my_robot/meshes/wheel_shaft.STL" scale="0.001 0.001 0.001"/>
      </geometry>
      <material name="black" />
    </visual>
    <collision>
      <origin xyz="0 0 0"/>
      <geometry>
        <mesh filename="package://my_robot/meshes/wheel_shaft.STL" scale="0.001 0.001 0.001"/>
      </geometry>
    </collision>
    <inertial>
      <origin xyz="0 0.01221 0" rpy="0 0 0"/>
      <mass value="0.055"/>
      <inertia
        ixx="0.000021370" ixy="0" ixz="0"
        iyy="0.000009966" iyz="0"
        izz="0.000021370"/>
    </inertial>
  </link>

<!--left_wheel_shaft_joint-->
  <joint name="left_wheel_shaft_joint" type="fixed">
    <origin xyz="0.005 -0.032 0.0" rpy="${PI} 0 0" />
    <parent link="chassis"/>
    <child link="left_wheel_shaft" />
  </joint>



<!--back_left_wheel_shaft-->
  <link name="back_left_wheel_shaft">
    <visual>
      <origin xyz="0 0 0" rpy="0 0 0" />
      <geometry>
        <mesh filename="package://my_robot/meshes/wheel_shaft.STL" scale="0.001 0.001 0.001"/>
      </geometry>
      <material name="black" />
    </visual>
    <collision>
      <origin xyz="0 0 0"/>
      <geometry>
        <mesh filename="package://my_robot/meshes/wheel_shaft.STL" scale="0.001 0.001 0.001"/>
      </geometry>
    </collision>
    <inertial>
      <origin xyz="0 0.01221 0" rpy="0 0 0"/>
      <mass value="0.055"/>
      <inertia
        ixx="0.000021370" ixy="0" ixz="0"
        iyy="0.000009966" iyz="0"
        izz="0.000021370"/>
    </inertial>
  </link>

<!--back_left_wheel_shaft_joint-->
  <joint name="back_left_wheel_shaft_joint" type="fixed">
    <origin xyz="-0.150 -0.032 0.0" rpy="${PI} 0 0" />
    <parent link="chassis"/>
    <child link="back_left_wheel_shaft" />
  </joint>

<!--left_wheel_hinge-->
  <joint name="left_wheel_hinge" type="continuous">
    <origin xyz="0 0.042 0" rpy="0 0 0" />
    <parent link="left_wheel_shaft"/>
    <child link="left_wheel" />
    <axis xyz="0 1 0"/>
  </joint>

<!-- left_wheel--> 
  <link name="left_wheel">
    <visual>
      <origin xyz="0 0 0" rpy="0 0 0" />
      <geometry>
        <mesh filename="package://my_robot/meshes/wheel_left.STL" scale="0.001 0.001 0.001"/>
      </geometry>
      <material name="light_grey" />
    </visual>
    <collision>
      <origin xyz="0 0 0" rpy="${PI/2} 0 0"/>
      <geometry>
        <cylinder radius="${wheel_radius}" length="${wheel_width}"/>
      </geometry>
    </collision>
    <inertial>
      <origin xyz="0.0 0.0 0.0" rpy="0 0 0"/>
      <mass value="0.3844"/>
      <!-- Inertia based on cylinder -->
      <inertia
        ixx="0.000324824" ixy="0" ixz="0"
        iyy="0.000480000" iyz="0"
        izz="0.000324824"/>
    </inertial>
  </link>

<!--back_left_wheel_hinge-->
  <joint name="back_left_wheel_hinge" type="continuous">
    <origin xyz="0 0.042 0" rpy="0 0 0" />
    <parent link="back_left_wheel_shaft"/>
    <child link="back_left_wheel" />
    <axis xyz="0 1 0"/>
  </joint>

<!--back_left_wheel-->
  <link name="back_left_wheel">
    <visual>
      <origin xyz="0 0 0" rpy="0 0 0" />
      <geometry>
        <mesh filename="package://my_robot/meshes/wheel_right.STL" scale="0.001 0.001 0.001"/>
      </geometry>
      <material name="light_grey" />
    </visual>
    <collision>
      <origin xyz="0 0 0" rpy="${PI/2} 0 0"/>
      <geometry>
        <cylinder radius="${wheel_radius}" length="${wheel_width}"/>
      </geometry>
    </collision>
    <inertial>
      <origin xyz="0.0 0.0 0.0" rpy="0 0 0"/>
      <mass value="0.3844"/>
      <!-- Inertia based on cylinder -->
      <inertia
        ixx="0.000324824" ixy="0" ixz="0"
        iyy="0.000480000" iyz="0"
        izz="0.000324824"/>
    </inertial>
  </link>
<!--right_wheel_hinge-->
  <joint name="right_wheel_hinge" type="continuous">
    <origin xyz="0 0.042 0" rpy="0 0 0" />
    <parent link="right_wheel_shaft"/>
    <child link="right_wheel" />
    <axis xyz="0 1 0"/>
  </joint>

<!--right_wheel-->
  <link name="right_wheel">
    <visual>
      <origin xyz="0 0 0" rpy="0 0 0" />
      <geometry>
        <mesh filename="package://my_robot/meshes/wheel_right.STL" scale="0.001 0.001 0.001"/>
      </geometry>
      <material name="light_grey" />
    </visual>
    <collision>
      <origin xyz="0 0 0" rpy="${PI/2} 0 0"/>
      <geometry>
        <cylinder radius="${wheel_radius}" length="${wheel_width}"/>
      </geometry>
    </collision>
    <inertial>
      <origin xyz="0.0 0.0 0.0" rpy="0 0 0"/>
      <mass value="0.3844"/>
      <!-- Inertia based on cylinder -->
      <inertia
        ixx="0.000324824" ixy="0" ixz="0"
        iyy="0.000480000" iyz="0"
        izz="0.000324824"/>
    </inertial>
  </link>

<!-- back_right_wheel_hinge--> 
  <joint name="back_right_wheel_hinge" type="continuous">
    <origin xyz="0 0.042 0" rpy="0 0 0" />
    <parent link="back_right_wheel_shaft"/>
    <child link="back_right_wheel" />
    <axis xyz="0 1 0"/>
  </joint>

<!--back_right_wheel-->
  <link name="back_right_wheel">
    <visual>
      <origin xyz="0 0 0" rpy="0 0 0" />
      <geometry>
        <mesh filename="package://my_robot/meshes/wheel_left.STL" scale="0.001 0.001 0.001"/>
      </geometry>
      <material name="light_grey" />
    </visual>
    <collision>
      <origin xyz="0 0 0" rpy="${PI/2} 0 0"/>
      <geometry>
        <cylinder radius="${wheel_radius}" length="${wheel_width}"/>
      </geometry>
    </collision>
    <inertial>
      <origin xyz="0.0 0.0 0.0" rpy="0 0 0"/>
      <mass value="0.3844"/>
      <!-- Inertia based on cylinder -->
      <inertia
        ixx="0.000324824" ixy="0" ixz="0"
        iyy="0.000480000" iyz="0"
        izz="0.000324824"/>
    </inertial>
  </link>

<!--Link (camera)-->
  <link name='camera'>
    <inertial>
      <origin xyz="0 0 0" rpy="0 0 0"/>
      <mass value="0.1"/>
      <box_inertia m="0.1" x="0.008" y="0.03" z="0.03"/>
      <inertia
          ixx="1e-6" ixy="0" ixz="0"
          iyy="1e-6" iyz="0"
          izz="1e-6"
      />
    </inertial>

    <visual name='camera_visual'>
      <origin xyz="0 0 0" rpy="0 0 0"/>
      <geometry>
        <box size=".008 .03 .03"/>
      </geometry>
    </visual>

    <collision name='camera_collision'>
      <origin xyz="0 0 0" rpy="0 0 0"/>
      <geometry>
        <box size=".008 .03 .03"/>
      </geometry>
    </collision>
  </link>

  <!--Joint (camera)-->
  <joint type="fixed" name="camera_joint">
    <origin xyz="0.06 0.04 0.06" rpy="0 0 0"/>
     <parent link="chassis"/>
     <child link="camera"/>
     <axis xyz="0 1 0"/>
  </joint>
  <gazebo reference="camera">
    <material>Gazebo/Green</material>
  </gazebo>


 <!--link (sensor-link)-->
  <link name="front_sensor">
    <visual>
      <origin xyz="0 0 0" rpy="${PI/2} 0 0" />
      <geometry>
        <mesh filename="package://my_robot/meshes/urm04.STL" scale="0.001 0.001 0.001"/>
      </geometry>
      <material name="black" />
    </visual>
  </link>
  <!--Joint (sensor-joint)-->
  <joint name="front_sensor_joint" type="fixed">
    <origin xyz="0.06 0.04 0.02" rpy="0 0 0" />
    <parent link="chassis"/>
    <child link="front_sensor" />
  </joint>



  <!-- Include controller plugin for Gazebo -->
  <!--<xacro:include filename="$(find nexus_4wd_mecanum_description)/urdf/nexus_4wd_mecanum.gazebo" />-->

  <!-- Include URM04 ultrasonic range finders -->
  <!--<xacro:include filename="$(find my_robot)/urdf/urm04_sensor.xacro"/>-->
  <!-- front sensor -->
  <!--<xacro:urm04_sensor frame_name="front_sensor" ros_topic="front_sensor" update_rate="10" min_range="0.04" max_range="2.5" horizontal_field_of_view="1.04" vertical_field_of_view="0.04" ray_count="2" />
--> 



</robot>
